[2024-03-09 17:25:20,007: INFO: main: test log]
[2024-03-09 17:29:26,425: INFO: main: test log]
[2024-03-09 17:29:44,740: INFO: main: test log 2]
[2024-03-15 16:05:02,062: INFO: main: >>>>>>> stage Data Ingestion Stage started <<<<<<<]
[2024-03-15 16:05:02,063: INFO: common: yaml file: config/config.yaml loaded successfully]
[2024-03-15 16:05:02,063: INFO: common: yaml file: params.yaml loaded successfully]
[2024-03-15 16:05:02,064: INFO: common: created directory at: artifacts]
[2024-03-15 16:05:02,064: INFO: common: created directory at: artifacts/data_ingestion]
[2024-03-15 16:05:02,064: ERROR: main: __init__() got an unexpected keyword argument 'root_dir']
Traceback (most recent call last):
  File "main.py", line 9, in <module>
    obj.main()
  File "/home/dc/e2e_kidney_disease_classifier/End-to-End-Kidney-Tumor-Classification/src/cnnClassifier/pipeline/stage_01_data_ingestion.py", line 14, in main
    data_ingestion_config = config.get_data_ingestion_config()
  File "/home/dc/e2e_kidney_disease_classifier/End-to-End-Kidney-Tumor-Classification/src/cnnClassifier/config/configuration.py", line 23, in get_data_ingestion_config
    data_ingestion_config = DataIngestionConfig(
TypeError: __init__() got an unexpected keyword argument 'root_dir'
[2024-03-15 16:07:27,422: INFO: main: >>>>>>> stage Data Ingestion Stage started <<<<<<<]
[2024-03-15 16:07:27,423: INFO: common: yaml file: config/config.yaml loaded successfully]
[2024-03-15 16:07:27,423: INFO: common: yaml file: params.yaml loaded successfully]
[2024-03-15 16:07:27,423: INFO: common: created directory at: artifacts]
[2024-03-15 16:07:27,423: INFO: common: created directory at: artifacts/data_ingestion]
[2024-03-15 16:07:27,424: ERROR: main: [Errno 2] No such file or directory: 'artifacts/data_ingestion/data.zip']
Traceback (most recent call last):
  File "main.py", line 9, in <module>
    obj.main()
  File "/home/dc/e2e_kidney_disease_classifier/End-to-End-Kidney-Tumor-Classification/src/cnnClassifier/pipeline/stage_01_data_ingestion.py", line 17, in main
    data_ingestion.extract_zip_file()
  File "/home/dc/e2e_kidney_disease_classifier/End-to-End-Kidney-Tumor-Classification/src/cnnClassifier/components/data_ingestion.py", line 40, in extract_zip_file
    with zipfile.ZipFile(self.config.local_data_file, 'r') as zip_ref:
  File "/home/dc/anaconda3/envs/kidney_tumor_classifier/lib/python3.8/zipfile.py", line 1251, in __init__
    self.fp = io.open(file, filemode)
FileNotFoundError: [Errno 2] No such file or directory: 'artifacts/data_ingestion/data.zip'
[2024-03-15 16:09:13,288: INFO: main: >>>>>>> stage Data Ingestion Stage started <<<<<<<]
[2024-03-15 16:09:13,289: INFO: common: yaml file: config/config.yaml loaded successfully]
[2024-03-15 16:09:13,289: INFO: common: yaml file: params.yaml loaded successfully]
[2024-03-15 16:09:13,289: INFO: common: created directory at: artifacts]
[2024-03-15 16:09:13,289: INFO: common: created directory at: artifacts/data_ingestion]
[2024-03-15 16:09:13,290: ERROR: main: [Errno 2] No such file or directory: 'artifacts/data_ingestion/data.zip']
Traceback (most recent call last):
  File "main.py", line 9, in <module>
    obj.main()
  File "/home/dc/e2e_kidney_disease_classifier/End-to-End-Kidney-Tumor-Classification/src/cnnClassifier/pipeline/stage_01_data_ingestion.py", line 17, in main
    data_ingestion.extract_zip_file()
  File "/home/dc/e2e_kidney_disease_classifier/End-to-End-Kidney-Tumor-Classification/src/cnnClassifier/components/data_ingestion.py", line 40, in extract_zip_file
    with zipfile.ZipFile(self.config.local_data_file, 'r') as zip_ref:
  File "/home/dc/anaconda3/envs/kidney_tumor_classifier/lib/python3.8/zipfile.py", line 1251, in __init__
    self.fp = io.open(file, filemode)
FileNotFoundError: [Errno 2] No such file or directory: 'artifacts/data_ingestion/data.zip'
[2024-03-15 16:09:37,087: INFO: main: >>>>>>> stage Data Ingestion Stage started <<<<<<<]
[2024-03-15 16:09:37,088: INFO: common: yaml file: config/config.yaml loaded successfully]
[2024-03-15 16:09:37,088: INFO: common: yaml file: params.yaml loaded successfully]
[2024-03-15 16:09:37,088: INFO: common: created directory at: artifacts]
[2024-03-15 16:09:37,088: INFO: common: created directory at: artifacts/data_ingestion]
[2024-03-15 16:09:37,089: ERROR: main: [Errno 2] No such file or directory: 'artifacts/data_ingestion/data.zip']
Traceback (most recent call last):
  File "main.py", line 9, in <module>
    obj.main()
  File "/home/dc/e2e_kidney_disease_classifier/End-to-End-Kidney-Tumor-Classification/src/cnnClassifier/pipeline/stage_01_data_ingestion.py", line 17, in main
    data_ingestion.extract_zip_file()
  File "/home/dc/e2e_kidney_disease_classifier/End-to-End-Kidney-Tumor-Classification/src/cnnClassifier/components/data_ingestion.py", line 40, in extract_zip_file
    with zipfile.ZipFile(self.config.local_data_file, 'r') as zip_ref:
  File "/home/dc/anaconda3/envs/kidney_tumor_classifier/lib/python3.8/zipfile.py", line 1251, in __init__
    self.fp = io.open(file, filemode)
FileNotFoundError: [Errno 2] No such file or directory: 'artifacts/data_ingestion/data.zip'
[2024-03-15 16:10:08,633: INFO: main: >>>>>>> stage Data Ingestion Stage started <<<<<<<]
[2024-03-15 16:10:08,634: INFO: common: yaml file: config/config.yaml loaded successfully]
[2024-03-15 16:10:08,634: INFO: common: yaml file: params.yaml loaded successfully]
[2024-03-15 16:10:08,634: INFO: common: created directory at: artifacts]
[2024-03-15 16:10:08,634: INFO: common: created directory at: artifacts/data_ingestion]
[2024-03-15 16:10:08,634: INFO: data_ingestion: Downloading data from https://drive.google.com/file/d/1Mb1kHZD0FSa3VrV7xebCy_7VkJ7rgevf/view?usp=sharing into file artifacts/data_ingestion/data.zip]
[2024-03-15 16:20:46,361: INFO: data_ingestion: Downloaded data from https://drive.google.com/file/d/1Mb1kHZD0FSa3VrV7xebCy_7VkJ7rgevf/view?usp=sharing into file artifacts/data_ingestion/data.zip]
[2024-03-15 16:20:53,228: INFO: main: >>>>>>> stage Data Ingestion Stage completed <<<<<<< 

x==========x]
